============================= test session starts =============================
platform win32 -- Python 3.13.2, pytest-8.3.5, pluggy-1.5.0 -- c:\Users\kevin\OneDrive\Desktop\Atlas-Backend\.venv\Scripts\python.exe
cachedir: .pytest_cache
rootdir: C:\Users\kevin\OneDrive\Desktop\Atlas-Backend
plugins: anyio-4.9.0, mock-3.14.0
collecting ... collected 2 items / 3 errors

=================================== ERRORS ====================================
__________________ ERROR collecting app/tests/test_agents.py __________________
ImportError while importing test module 'C:\Users\kevin\OneDrive\Desktop\Atlas-Backend\app\tests\test_agents.py'.
Hint: make sure your test modules/packages have valid Python names.
Traceback:
.venv\Lib\site-packages\_pytest\python.py:493: in importtestmodule
    mod = import_path(
.venv\Lib\site-packages\_pytest\pathlib.py:587: in import_path
    importlib.import_module(module_name)
..\..\..\AppData\Local\Programs\Python\Python313\Lib\importlib\__init__.py:88: in import_module
    return _bootstrap._gcd_import(name[level:], package, level)
<frozen importlib._bootstrap>:1387: in _gcd_import
    ???
<frozen importlib._bootstrap>:1360: in _find_and_load
    ???
<frozen importlib._bootstrap>:1331: in _find_and_load_unlocked
    ???
<frozen importlib._bootstrap>:935: in _load_unlocked
    ???
.venv\Lib\site-packages\_pytest\assertion\rewrite.py:185: in exec_module
    exec(co, module.__dict__)
app\tests\test_agents.py:4: in <module>
    from app.main import app
app\main.py:12: in <module>
    from app.core import error_handlers
app\core\error_handlers.py:6: in <module>
    from app.db.supabase_client import SupabaseClientError
app\db\__init__.py:1: in <module>
    from .supabase_client import get_supabase_client, SupabaseClientError
app\db\supabase_client.py:1: in <module>
    from supabase import create_client, Client
E   ModuleNotFoundError: No module named 'supabase'
___________________ ERROR collecting app/tests/test_chat.py ___________________
app\tests\test_chat.py:3: in <module>
    with patch("app.db.supabase_client.get_supabase_client") as mock_supabase_client:
..\..\..\AppData\Local\Programs\Python\Python313\Lib\unittest\mock.py:1479: in __enter__
    self.target = self.getter()
..\..\..\AppData\Local\Programs\Python\Python313\Lib\pkgutil.py:528: in resolve_name
    result = getattr(result, p)
E   AttributeError: module 'app' has no attribute 'db'
_________________ ERROR collecting app/tests/test_workflow.py _________________
ImportError while importing test module 'C:\Users\kevin\OneDrive\Desktop\Atlas-Backend\app\tests\test_workflow.py'.
Hint: make sure your test modules/packages have valid Python names.
Traceback:
.venv\Lib\site-packages\_pytest\python.py:493: in importtestmodule
    mod = import_path(
.venv\Lib\site-packages\_pytest\pathlib.py:587: in import_path
    importlib.import_module(module_name)
..\..\..\AppData\Local\Programs\Python\Python313\Lib\importlib\__init__.py:88: in import_module
    return _bootstrap._gcd_import(name[level:], package, level)
<frozen importlib._bootstrap>:1387: in _gcd_import
    ???
<frozen importlib._bootstrap>:1360: in _find_and_load
    ???
<frozen importlib._bootstrap>:1331: in _find_and_load_unlocked
    ???
<frozen importlib._bootstrap>:935: in _load_unlocked
    ???
.venv\Lib\site-packages\_pytest\assertion\rewrite.py:185: in exec_module
    exec(co, module.__dict__)
app\tests\test_workflow.py:3: in <module>
    from app.main import app
app\main.py:12: in <module>
    from app.core import error_handlers
app\core\error_handlers.py:6: in <module>
    from app.db.supabase_client import SupabaseClientError
app\db\__init__.py:1: in <module>
    from .supabase_client import get_supabase_client, SupabaseClientError
app\db\supabase_client.py:1: in <module>
    from supabase import create_client, Client
E   ModuleNotFoundError: No module named 'supabase'
=========================== short test summary info ===========================
ERROR app/tests/test_agents.py
ERROR app/tests/test_chat.py - AttributeError: module 'app' has no attribute 'db'
ERROR app/tests/test_workflow.py
!!!!!!!!!!!!!!!!!!! Interrupted: 3 errors during collection !!!!!!!!!!!!!!!!!!!
============================== 3 errors in 0.75s ==============================
