============================= test session starts =============================
platform win32 -- Python 3.10.11, pytest-8.3.5, pluggy-1.5.0 -- C:\Users\kevin\AppData\Local\Programs\Python\Python310\python.exe
cachedir: .pytest_cache
rootdir: C:\Users\kevin\OneDrive\Desktop\Atlas-Backend
plugins: anyio-4.9.0, ddtrace-1.13.0, asyncio-0.21.1, cov-4.1.0, mock-3.14.0
asyncio: mode=strict
collecting ... collected 0 items / 2 errors

=================================== ERRORS ====================================
__________________ ERROR collecting app/tests/test_agents.py __________________
ImportError while importing test module 'C:\Users\kevin\OneDrive\Desktop\Atlas-Backend\app\tests\test_agents.py'.
Hint: make sure your test modules/packages have valid Python names.
Traceback:
..\..\..\AppData\Local\Programs\Python\Python310\lib\importlib\__init__.py:126: in import_module
    return _bootstrap._gcd_import(name[level:], package, level)
..\..\..\AppData\Local\Programs\Python\Python310\lib\site-packages\ddtrace\internal\module.py:216: in _exec_module
    self.loader.exec_module(module)
app\tests\test_agents.py:4: in <module>
    from main import app
..\..\..\AppData\Local\Programs\Python\Python310\lib\site-packages\ddtrace\internal\module.py:216: in _exec_module
    self.loader.exec_module(module)
main.py:7: in <module>
    from app.core.config import settings
E   ImportError: cannot import name 'settings' from 'app.core.config' (C:\Users\kevin\OneDrive\Desktop\Atlas-Backend\app\core\config.py)
___________________ ERROR collecting app/tests/test_chat.py ___________________
ImportError while importing test module 'C:\Users\kevin\OneDrive\Desktop\Atlas-Backend\app\tests\test_chat.py'.
Hint: make sure your test modules/packages have valid Python names.
Traceback:
..\..\..\AppData\Local\Programs\Python\Python310\lib\importlib\__init__.py:126: in import_module
    return _bootstrap._gcd_import(name[level:], package, level)
..\..\..\AppData\Local\Programs\Python\Python310\lib\site-packages\ddtrace\internal\module.py:216: in _exec_module
    self.loader.exec_module(module)
app\tests\test_chat.py:18: in <module>
    from main import app
..\..\..\AppData\Local\Programs\Python\Python310\lib\site-packages\ddtrace\internal\module.py:216: in _exec_module
    self.loader.exec_module(module)
main.py:7: in <module>
    from app.core.config import settings
E   ImportError: cannot import name 'settings' from 'app.core.config' (C:\Users\kevin\OneDrive\Desktop\Atlas-Backend\app\core\config.py)
=========================== short test summary info ===========================
ERROR app/tests/test_agents.py
ERROR app/tests/test_chat.py
!!!!!!!!!!!!!!!!!!! Interrupted: 2 errors during collection !!!!!!!!!!!!!!!!!!!
======================= 19 warnings, 2 errors in 1.20s ========================
